Workbook

Sheet Orders
A1: Order ID | B1: Customer ID | C1: Customer Country | D1: OrderDate | E1: OrderTime | F1: OrderMonth(Nos) | G1: OrderDay | H1: OrderMonth | I1: Order Source | J1: Sales POC | K1: Order Value | L1: QuartileCheck | M1: Age
A2: 1597 | B2: 856 | C2: USA | D2: 45275 | E2: 0.53472222 | F2: =MONTH(D2) -> 12 | G2: =TEXT(D2,"dddd") -> Friday | H2: =TEXT(D2,"mmmm") -> December | I2: Other | J2: Kwai Yu | K2: 412 | L2: =IF(OR(K2<Answers!$C$16,Orders!K2>Answers!$C$17),"Yes","No") -> No | M2: =VLOOKUP(B2,Customers!$A$1:$E$2501,4,0) -> 59
A3: 2011 | B3: 525 | C3: India | D3: 45045 | E3: 0.48611111 | F3: =MONTH(D3) -> 4 | G3: =TEXT(D3,"dddd") -> Saturday | H3: =TEXT(D3,"mmmm") -> April | I3: Whatsapp | J3: Paul Henriot | K3: 4551 | L3: =IF(OR(K3<Answers!$C$16,Orders!K3>Answers!$C$17),"Yes","No") -> No | M3: =VLOOKUP(B3,Customers!$A$1:$E$2501,4,0) -> 20
A4: 2822 | B4: 1614 | C4: USA | D4: 45290 | E4: 0.51458333 | F4: =MONTH(D4) -> 12 | G4: =TEXT(D4,"dddd") -> Saturday | H4: =TEXT(D4,"mmmm") -> December | I4: Whatsapp | J4: Daniel Da Cunha | K4: 3960 | L4: =IF(OR(K4<Answers!$C$16,Orders!K4>Answers!$C$17),"Yes","No") -> No | M4: =VLOOKUP(B4,Customers!$A$1:$E$2501,4,0) -> 37
A5: 2889 | B5: 743 | C5: USA | D5: 45258 | E5: 0.52152778 | F5: =MONTH(D5) -> 11 | G5: =TEXT(D5,"dddd") -> Tuesday | H5: =TEXT(D5,"mmmm") -> November | I5: Whatsapp | J5: Julie Young | K5: 8397 | L5: =IF(OR(K5<Answers!$C$16,Orders!K5>Answers!$C$17),"Yes","No") -> No | M5: =VLOOKUP(B5,Customers!$A$1:$E$2501,4,0) -> 29
A6: 3971 | B6: 20 | C6: USA | D6: 45225 | E6: 36841 | F6: =MONTH(D6) -> 10 | G6: =TEXT(D6,"dddd") -> Thursday | H6: =TEXT(D6,"mmmm") -> October | I6: Website | J6: Julie Brown | K6: 5545 | L6: =IF(OR(K6<Answers!$C$16,Orders!K6>Answers!$C$17),"Yes","No") -> No | M6: =VLOOKUP(B6,Customers!$A$1:$E$2501,4,0) -> 38
A7: 4111 | B7: 1367 | C7: Italy | D7: 44993 | E7: 0.45277778 | F7: =MONTH(D7) -> 3 | G7: =TEXT(D7,"dddd") -> Wednesday | H7: =TEXT(D7,"mmmm") -> March | I7: App | J7: Juri Hirano | K7: 7800 | L7: =IF(OR(K7<Answers!$C$16,Orders!K7>Answers!$C$17),"Yes","No") -> No | M7: =VLOOKUP(B7,Customers!$A$1:$E$2501,4,0) -> 25
A8: 4801 | B8: 945 | C8: France | D8: 44975 | E8: 0.51597222 | F8: =MONTH(D8) -> 2 | G8: =TEXT(D8,"dddd") -> Saturday | H8: =TEXT(D8,"mmmm") -> February | I8: Other | J8: Martine Rance | K8: 4674 | L8: =IF(OR(K8<Answers!$C$16,Orders!K8>Answers!$C$17),"Yes","No") -> No | M8: =VLOOKUP(B8,Customers!$A$1:$E$2501,4,0) -> 34
A9: 5719 | B9: 218 | C9: France | D9: 45253 | E9: 36800 | F9: =MONTH(D9) -> 11 | G9: =TEXT(D9,"dddd") -> Thursday | H9: =TEXT(D9,"mmmm") -> November | I9: Website | J9: Veysel Oeztan | K9: 5954 | L9: =IF(OR(K9<Answers!$C$16,Orders!K9>Answers!$C$17),"Yes","No") -> No | M9: =VLOOKUP(B9,Customers!$A$1:$E$2501,4,0) -> 34
A10: 5846 | B10: 264 | C10: USA | D10: 45283 | E10: 0.055555556 | F10: =MONTH(D10) -> 12 | G10: =TEXT(D10,"dddd") -> Saturday | H10: =TEXT(D10,"mmmm") -> December | I10: Website | J10: Julie Murphy | K10: 9887 | L10: =IF(OR(K10<Answers!$C$16,Orders!K10>Answers!$C$17),"Yes","No") -> No | M10: =VLOOKUP(B10,Customers!$A$1:$E$2501,4,0) -> 46
A11: 7615 | B11: 566 | C11: USA | D11: 45233 | E11: 0.49027778 | F11: =MONTH(D11) -> 11 | G11: =TEXT(D11,"dddd") -> Friday | H11: =TEXT(D11,"mmmm") -> November | I11: Whatsapp | J11: Dominique Perrier | K11: 8303 | L11: =IF(OR(K11<Answers!$C$16,Orders!K11>Answers!$C$17),"Yes","No") -> No | M11: =VLOOKUP(B11,Customers!$A$1:$E$2501,4,0) -> 74
A12: 8568 | B12: 1414 | C12: USA | D12: 45133 | E12: 36842 | F12: =MONTH(D12) -> 7 | G12: =TEXT(D12,"dddd") -> Wednesday | H12: =TEXT(D12,"mmmm") -> July | I12: App | J12: Peter Ferguson | K12: 8969 | L12: =IF(OR(K12<Answers!$C$16,Orders!K12>Answers!$C$17),"Yes","No") -> No | M12: =VLOOKUP(B12,Customers!$A$1:$E$2501,4,0) -> 28
A13: 9339 | B13: 1681 | C13: Spain | D13: 45278 | E13: 0.52708333 | F13: =MONTH(D13) -> 12 | G13: =TEXT(D13,"dddd") -> Monday | H13: =TEXT(D13,"mmmm") -> December | I13: App | J13: Michael Frick | K13: 2782 | L13: =IF(OR(K13<Answers!$C$16,Orders!K13>Answers!$C$17),"Yes","No") -> No | M13: =VLOOKUP(B13,Customers!$A$1:$E$2501,4,0) -> 38
... A2501: 1682358 | B2501: 567 | C2501: Australia | D2501: 45012 | E2501: 0.47152778 | F2501: =MONTH(D2501) -> 3 | G2501: =TEXT(D2501,"dddd") -> Monday | H2501: =TEXT(D2501,"mmmm") -> March | I2501: Website | J2501: Helen Bennett | K2501: 4540 | L2501: =IF(OR(K2501<Answers!$C$16,Orders!K2501>Answers!$C$17),"Yes","No") -> No | M2501: =VLOOKUP(B2501,Customers!$A$1:$E$2501,4,0) -> 37

Sheet Customers
A1: Customer ID | B1: Customer Country | C1: Gender | D1: Age | E1: Category
A2: 1 | B2: France | C2: M | D2: 31 | E2: A
A3: 2 | B3: Spain | C3: M | D3: 49 | E3: A
A4: 3 | B4: USA | C4: M | D4: 39 | E4: A
A5: 4 | B5: Australia | C5: M | D5: 39.666667 | E5: A
A6: 5 | B6: Denmark | C6: M | D6: 81 | E6: A
A7: 6 | B7: USA | C7: F | D7: 62 | E7: A
A8: 7 | B8: Singapore | C8: M | D8: 76 | E8: A
A9: 8 | B9: France | C9: F | D9: 70 | E9: A
A10: 9 | B10: France | C10: F | D10: 75 | E10: A
A11: 10 | B11: Norway | C11: F | D11: 32 | E11: A
A12: 11 | B12: USA | C12: F | D12: 82 | E12: A
A13: 12 | B13: Spain | C13: F | D13: 65 | E13: A
... A2501: 2500 | B2501: Denmark | C2501: F | D2501: 46 | E2501: E

Sheet Sales Targets
A1: Sales POC | B1: Sales Manager First Name | C1: Sales Manager Last Name | D1: Full Name | E1: Sales Team | F1: 2023 Sales Target | G1: Actual Sales | H1: Target Met/ Target Not Met | I1: Sales Shortfall | J1: % Target Reached
A2: Kalle Suominen | B2: Amelia | C2: Johnson | D2: =_xlfn.CONCAT(B2," ",C2) -> Amelia Johnson | E2: Epsilon | F2: 100000 | G2: =SUMIF(Orders!$J$1:$J$2501,'Sales Targets'!A2,Orders!$K$1:$K$2501) -> 135017 | H2: {=_xlfn.IFS(G2<F2,"Target Not Met",G2=F2,"Target Met",G2>F2,"Target Exceeded")} -> Target Exceeded | I2: =IF(G2<F2,F2-G2,0) -> 0 | J2: =G2/F2 -> 1.35017
A3: Julie Brown | B3: Lukas | C3: Schmidt | D3: =_xlfn.CONCAT(B3," ",C3) -> Lukas Schmidt | E3: Alpha | F3: 200000 | G3: =SUMIF(Orders!$J$1:$J$2501,'Sales Targets'!A3,Orders!$K$1:$K$2501) -> 192740 | H3: {=_xlfn.IFS(G3<F3,"Target Not Met",G3=F3,"Target Met",G3>F3,"Target Exceeded")} -> Target Not Met | I3: =IF(G3<F3,F3-G3,0) -> 7260 | J3: =G3/F3 -> 0.9637
A4: Jeff Young | B4: Olivia | C4: Jensen | D4: =_xlfn.CONCAT(B4," ",C4) -> Olivia Jensen | E4: Beta | F4: 200000 | G4: =SUMIF(Orders!$J$1:$J$2501,'Sales Targets'!A4,Orders!$K$1:$K$2501) -> 227134 | H4: {=_xlfn.IFS(G4<F4,"Target Not Met",G4=F4,"Target Met",G4>F4,"Target Exceeded")} -> Target Exceeded | I4: =IF(G4<F4,F4-G4,0) -> 0 | J4: =G4/F4 -> 1.13567
A5: Kyung Yu | B5: Sofia | C5: Laine | D5: =_xlfn.CONCAT(B5," ",C5) -> Sofia Laine | E5: Gamma | F5: 100000 | G5: =SUMIF(Orders!$J$1:$J$2501,'Sales Targets'!A5,Orders!$K$1:$K$2501) -> 130274 | H5: {=_xlfn.IFS(G5<F5,"Target Not Met",G5=F5,"Target Met",G5>F5,"Target Exceeded")} -> Target Exceeded | I5: =IF(G5<F5,F5-G5,0) -> 0 | J5: =G5/F5 -> 1.30274
A6: Adrian Huxley | B6: Chloe | C6: Dupont | D6: =_xlfn.CONCAT(B6," ",C6) -> Chloe Dupont | E6: Beta | F6: 200000 | G6: =SUMIF(Orders!$J$1:$J$2501,'Sales Targets'!A6,Orders!$K$1:$K$2501) -> 182094 | H6: {=_xlfn.IFS(G6<F6,"Target Not Met",G6=F6,"Target Met",G6>F6,"Target Exceeded")} -> Target Not Met | I6: =IF(G6<F6,F6-G6,0) -> 17906 | J6: =G6/F6 -> 0.91047
A7: Kwai Yu | B7: Alexander | C7: Müller | D7: =_xlfn.CONCAT(B7," ",C7) -> Alexander Müller | E7: Alpha | F7: 200000 | G7: =SUMIF(Orders!$J$1:$J$2501,'Sales Targets'!A7,Orders!$K$1:$K$2501) -> 219735 | H7: {=_xlfn.IFS(G7<F7,"Target Not Met",G7=F7,"Target Met",G7>F7,"Target Exceeded")} -> Target Exceeded | I7: =IF(G7<F7,F7-G7,0) -> 0 | J7: =G7/F7 -> 1.098675
A8: Jytte Petersen | B8: Liam | C8: O'Sullivan | D8: =_xlfn.CONCAT(B8," ",C8) -> Liam O'Sullivan | E8: Beta | F8: 100000 | G8: =SUMIF(Orders!$J$1:$J$2501,'Sales Targets'!A8,Orders!$K$1:$K$2501) -> 145221 | H8: {=_xlfn.IFS(G8<F8,"Target Not Met",G8=F8,"Target Met",G8>F8,"Target Exceeded")} -> Target Exceeded | I8: =IF(G8<F8,F8-G8,0) -> 0 | J8: =G8/F8 -> 1.45221
A9: Paul Henriot | B9: Sophia | C9: Rossi | D9: =_xlfn.CONCAT(B9," ",C9) -> Sophia Rossi | E9: Beta | F9: 200000 | G9: =SUMIF(Orders!$J$1:$J$2501,'Sales Targets'!A9,Orders!$K$1:$K$2501) -> 195983 | H9: {=_xlfn.IFS(G9<F9,"Target Not Met",G9=F9,"Target Met",G9>F9,"Target Exceeded")} -> Target Not Met | I9: =IF(G9<F9,F9-G9,0) -> 4017 | J9: =G9/F9 -> 0.979915
A10: Sue King | B10: Emma | C10: Hansen | D10: =_xlfn.CONCAT(B10," ",C10) -> Emma Hansen | E10: Gamma | F10: 100000 | G10: =SUMIF(Orders!$J$1:$J$2501,'Sales Targets'!A10,Orders!$K$1:$K$2501) -> 107896 | H10: {=_xlfn.IFS(G10<F10,"Target Not Met",G10=F10,"Target Met",G10>F10,"Target Exceeded")} -> Target Exceeded | I10: =IF(G10<F10,F10-G10,0) -> 0 | J10: =G10/F10 -> 1.07896
A11: Victoria Ashworth | B11: Ethan | C11: Lee | D11: =_xlfn.CONCAT(B11," ",C11) -> Ethan Lee | E11: Beta | F11: 250000 | G11: =SUMIF(Orders!$J$1:$J$2501,'Sales Targets'!A11,Orders!$K$1:$K$2501) -> 261093 | H11: {=_xlfn.IFS(G11<F11,"Target Not Met",G11=F11,"Target Met",G11>F11,"Target Exceeded")} -> Target Exceeded | I11: =IF(G11<F11,F11-G11,0) -> 0 | J11: =G11/F11 -> 1.044372
A12: Anna O'Hara | B12: Isabella | C12: Garcia | D12: =_xlfn.CONCAT(B12," ",C12) -> Isabella Garcia | E12: Alpha | F12: 200000 | G12: =SUMIF(Orders!$J$1:$J$2501,'Sales Targets'!A12,Orders!$K$1:$K$2501) -> 242439 | H12: {=_xlfn.IFS(G12<F12,"Target Not Met",G12=F12,"Target Met",G12>F12,"Target Exceeded")} -> Target Exceeded | I12: =IF(G12<F12,F12-G12,0) -> 0 | J12: =G12/F12 -> 1.212195
A13: Diego Freyre | B13: Noah | C13: Meier | D13: =_xlfn.CONCAT(B13," ",C13) -> Noah Meier | E13: Alpha | F13: 1000000 | G13: =SUMIF(Orders!$J$1:$J$2501,'Sales Targets'!A13,Orders!$K$1:$K$2501) -> 1089868 | H13: {=_xlfn.IFS(G13<F13,"Target Not Met",G13=F13,"Target Met",G13>F13,"Target Exceeded")} -> Target Exceeded | I13: =IF(G13<F13,F13-G13,0) -> 0 | J13: =G13/F13 -> 1.089868
... A93: Jesus Fernandez | B93: Ava | C93: Williams | D93: =_xlfn.CONCAT(B93," ",C93) -> Ava Williams | E93: Epsilon | F93: 50000 | G93: =SUMIF(Orders!$J$1:$J$2501,'Sales Targets'!A93,Orders!$K$1:$K$2501) -> 41950 | H93: {=_xlfn.IFS(G93<F93,"Target Not Met",G93=F93,"Target Met",G93>F93,"Target Exceeded")} -> Target Not Met | I93: =IF(G93<F93,F93-G93,0) -> 8050 | J93: =G93/F93 -> 0.839

Sheet Answers
B1: Missing Values
C2: CustomerCountry | D2: Order Source
B3: CountA | C3: =COUNTA(Orders!C2:C2501) -> 2500 | D3: =COUNTA(Orders!I2:I2501) -> 2500
B4: CountBlank | C4: =COUNTBLANK(Orders!C2:C2501) -> 0 | D4: =COUNTBLANK(Orders!I1:I2501) -> 0
B5: Difference | C5: =C3-C4 -> 2500 | D5: =D3-D4 -> 2500
B8: Data Cleaning
C9: OrderValue | D9: Age
B10: Q0 | C10: =QUARTILE(Orders!K1:K2501,0) -> 10 | D10: =QUARTILE(Customers!D1:D2501,0) -> 18
B11: Q1 | C11: =QUARTILE(Orders!K2:K2502,1) -> 2364 | D11: =QUARTILE(Customers!D2:D2502,1) -> 36
B12: Q2 | C12: =QUARTILE(Orders!K3:K2503,2) -> 4738 | D12: =QUARTILE(Customers!D3:D2503,2) -> 54
B13: Q3 | C13: =QUARTILE(Orders!K4:K2504,3) -> 7447.75 | D13: =QUARTILE(Customers!D4:D2504,3) -> 72
B14: Q4 | C14: =QUARTILE(Orders!K5:K2505,4) -> 9994 | D14: =QUARTILE(Customers!D5:D2505,4) -> 90
B15: IQR | C15: =C13-C11 -> 5083.75 | D15: =D13-D11 -> 36
B16: LowerBound | C16: =C11-1.5*C15 -> -5261.625 | D16: =D11-1.5*D15 -> -18
B17: HigherBound | C17: =C13+1.5*C15 -> 15073.375 | D17: =D13+1.5*D15 -> 126
B20: Data of 2nd half of year
B21: Sum of OrderValue | C21: =SUMIF(Orders!F1:F2501,">6",Orders!K1:K2501) -> 6095203
B22: Count of Orders Placed | C22: =COUNTIF(Orders!F1:F2501,">6") -> 1249
B24: Indian Customers | F24: Category | G24: Average Age
B25: Sum of OrderValue | C25: =SUMIF(Orders!C1:C2501,"India",Orders!K1:K2501) -> 1356737 | F25: A | G25: =AVERAGEIF(Customers!$E$2:$E$2501,Answers!F25,Customers!$D$2:$D$2501) -> 53.917333 | H25: Category D has the youngest Average age, with the average age 53
B26: Count of Orders Placed | C26: =COUNTIF(Orders!C1:C2501,"India") -> 281 | F26: B | G26: =AVERAGEIF(Customers!$E$2:$E$2501,Answers!F26,Customers!$D$2:$D$2501) -> 53.868
F27: C | G27: =AVERAGEIF(Customers!$E$2:$E$2501,Answers!F27,Customers!$D$2:$D$2501) -> 54.329333
F28: D | G28: =AVERAGEIF(Customers!$E$2:$E$2501,Answers!F28,Customers!$D$2:$D$2501) -> 53.02
B29: Orders via Whatsapp | F29: E | G29: =AVERAGEIF(Customers!$E$2:$E$2501,Answers!F29,Customers!$D$2:$D$2501) -> 54.670667
B30: Average OrderValue | C30: =AVERAGEIF(Orders!I1:I2501,"Whatsapp",Orders!K1:K2501) -> 4760.8231
F31: Category | G31: Highest Indian Males
B32: Orders on or after 15June2023 | F32: A | G32: =COUNTIFS(Customers!$C$1:$C$2501,"M",Customers!$E$1:$E$2501,Answers!F32,Customers!B1:B2501,"India") -> 44
B33: Count of Orders with customer age > 30 | C33: =COUNTIFS(Orders!$D$1:$D$2501,">=15-06-2023",Orders!$M$1:$M$2501,">30") -> 1083 | F33: B | G33: =COUNTIFS(Customers!$C$1:$C$2501,"M",Customers!$E$1:$E$2501,Answers!F33,Customers!B2:B2502,"India") -> 39 | H33: Category A has the highest number of Indian Males as customer which is 44
F34: C | G34: =COUNTIFS(Customers!$C$1:$C$2501,"M",Customers!$E$1:$E$2501,Answers!F34,Customers!B3:B2503,"India") -> 25
F35: D | G35: =COUNTIFS(Customers!$C$1:$C$2501,"M",Customers!$E$1:$E$2501,Answers!F35,Customers!B4:B2504,"India") -> 0
B36: Sales POC's who missed the target | D36: =COUNTIF('Sales Targets'!H1:H93,"Target Not Met") -> 55 | F36: E | G36: =COUNTIFS(Customers!$C$1:$C$2501,"M",Customers!$E$1:$E$2501,Answers!F36,Customers!B5:B2505,"India") -> 0
B37: Average Shortfall on sales on target | D37: =AVERAGEIF('Sales Targets'!H1:H93,"Target Not Met",'Sales Targets'!I1:I93) -> 21703.527
B40: Performed Target for Specific Sales POC's
B41: Sales POC Name | C41: Steve Frick
B42: Team Name | C42: =INDEX('Sales Targets'!$A$1:$J$93,MATCH(Answers!C41,'Sales Targets'!A1:A93,0),5) -> Delta
B43: Sales Target | C43: =INDEX('Sales Targets'!$A$1:$J$93,MATCH(C41,'Sales Targets'!$A$1:$A$93,0),6) -> 100000
B44: Actual Sales | C44: =INDEX('Sales Targets'!$A$1:$J$93,MATCH(C41,'Sales Targets'!$A$1:$A$93,0),7) -> 98119
B45: Difference | C45: =C43-C44 -> 1881
B47: Performed Target for Specific Sales POC's
B48: Sales POC Name | C48: Dean Cassidy
...

Sheet Orders Over Month
A3: Row Labels | B3: Count of Order ID | C3: Average of Order Value
A4: January | B4: 217 | C4: 4854.4286
A5: February | B5: 220 | C5: 4979.5909
A6: March | B6: 197 | C6: 5166.2234
A7: April | B7: 197 | C7: 4822.2335
A8: May | B8: 207 | C8: 4901.6425
A9: June | B9: 213 | C9: 4926.7606
A10: July | B10: 209 | C10: 4989.1962
A11: August | B11: 207 | C11: 5169.5797
A12: September | B12: 195 | C12: 4759.041
A13: October | B13: 201 | C13: 4673.4925
A14: November | B14: 229 | C14: 5236.1092
A15: December | B15: 208 | C15: 4403.3846
A16: Grand Total | B16: 2500 | C16: 4910.356

Sheet Customer over Country Sales
A3: Row Labels | B3: Count of Customer ID | C3: Sum of Order Value
A4: Australia | B4: 198 | C4: 974217
A5: Austria | B5: 43 | C5: 223916
A6: Denmark | B6: 66 | C6: 307260
A7: Finland | B7: 66 | C7: 324319
A8: France | B8: 323 | C8: 1637659
A9: Germany | B9: 58 | C9: 299656
A10: India | B10: 281 | C10: 1356737
A11: Ireland | B11: 20 | C11: 91966
A12: Italy | B12: 112 | C12: 538932
A13: N/A | B13: 7 | C13: 36818
A14: Norway | B14: 40 | C14: 195229
A15: Singapore | B15: 97 | C15: 486633
... A19: Grand Total | B19: 2500 | C19: 12275890

Sheet Orders Over Hours
A3: Row Labels | B3: Count of Order ID | C3: Average of Order Value
A4: 12 AM | B4: 475 | C4: 5020.7347
A5: 1 AM | B5: 466 | C5: 4928.9185
A6: 2 AM | B6: 40 | C6: 4712.075
A7: 4 AM | B7: 2 | C7: 6297.5
A8: 10 AM | B8: 154 | C8: 4927.0325
A9: 11 AM | B9: 569 | C9: 4695.0826
A10: 12 PM | B10: 794 | C10: 4990.9597
A11: Grand Total | B11: 2500 | C11: 4910.356
J20: `

Sheet Orders Over Days
A3: Row Labels | B3: Count of Order ID | C3: Average of Order Value
A4: Monday | B4: 386 | C4: 4856.5337
A5: Tuesday | B5: 366 | C5: 5073.2541
A6: Wednesday | B6: 346 | C6: 4803.1098
A7: Thursday | B7: 347 | C7: 4998.3141
A8: Friday | B8: 340 | C8: 4972.3765
A9: Saturday | B9: 368 | C9: 4669.6304
A10: Sunday | B10: 347 | C10: 5011.9135
A11: Grand Total | B11: 2500 | C11: 4910.356

Sheet Order Sources Trend
A3: Row Labels | B3: Count of Order ID
A4: App | B4: 622
A5: Other | B5: 608
A6: Website | B6: 637
A7: Whatsapp | B7: 633
A8: Grand Total | B8: 2500

Sheet Orders on AgeGroup Trend
A3: Row Labels | B3: Sum of Order Value | C3: Count of Order ID
A4: 18-27 | B4: 1852914 | C4: 369
A5: 28-37 | B5: 1721666 | C5: 349
A6: 38-47 | B6: 1585197 | C6: 330
A7: 48-57 | B7: 1503869 | C7: 303
A8: 58-67 | B8: 1921087 | C8: 392
A9: 68-77 | B9: 1588152 | C9: 330
A10: 78-87 | B10: 1637807 | C10: 340
A11: 88-97 | B11: 465198 | C11: 87
A12: Grand Total | B12: 12275890 | C12: 2500

Sheet Target on POC Trend
A3: Row Labels | B3: Count of Sales POC
A4: Target Exceeded | B4: 37
A5: Target Not Met | B5: 55
A6: Grand Total | B6: 92

Sheet Sales Team's Target Trend
A3: Row Labels | B3: Sum of 2023 Sales Target | C3: Sum of Actual Sales
A4: Alpha | B4: 3690000 | C4: 3864300
A5: Beta | B5: 2920000 | C5: 2717137
A6: Delta | B6: 2310000 | C6: 1999414
A7: Epsilon | B7: 1480000 | C7: 1360064
A8: Gamma | B8: 2410000 | C8: 2334975
A9: Grand Total | B9: 12810000 | C9: 12275890

Sheet Managers Sales Target
A1: Target Met/ Target Not Met | B1: (All)
A3: Row Labels | B3: Sum of 2023 Sales Target | C3: Sum of Actual Sales | E3: Highest Target of Managers
A4: Noah Meier | B4: 1300000 | C4: 1402941 | E4: Sr No. | F4: Manager Names | G4: Target Sales | H4: Actual Sales | I4: Target Met/Not Met
A5: Benjamin Chen | B5: 1300000 | C5: 1032580 | E5: 1 | F5: Noah Meier | G5: =INDEX($A$4:$C$34,MATCH(F5,$A$4:$A$34,0),2) -> 1300000 | H5: =INDEX($A$4:$C$34,MATCH(F5,$A$4:$A$34,0),3) -> 1402941 | I5: =IF(H5<G5,"Target Not Met",IF(H5=G5,"Taget Met","Target Exceeded")) -> Target Exceeded
A6: Benjamin Weber | B6: 550000 | C6: 466003 | E6: 2 | F6: Benjamin Chen | G6: =INDEX($A$4:$C$34,MATCH(F6,$A$4:$A$34,0),2) -> 1300000 | H6: =INDEX($A$4:$C$34,MATCH(F6,$A$4:$A$34,0),3) -> 1032580 | I6: =IF(H6<G6,"Target Not Met",IF(H6=G6,"Taget Met","Target Exceeded")) -> Target Not Met
A7: Marco Bianchi | B7: 500000 | C7: 489267
A8: Isabella Garcia | B8: 500000 | C8: 540410
A9: Liam O'Sullivan | B9: 450000 | C9: 352206 | E9: Noah Meier and Benjamin Chen assigned with Sales Target i.e. Rs 13,00,000/- Hence Noah Meier sucessfully Exceeded the Target while Benjamin Chen did not achieve the established goal.
A10: Sophia Rossi | B10: 450000 | C10: 406493
A11: Chloe Dupont | B11: 430000 | C11: 377693
A12: Ava Williams | B12: 400000 | C12: 355885
A13: Dev Patel | B13: 400000 | C13: 399805
A14: Daniela Hernandez | B14: 400000 | C14: 390703
A15: Lucas Nielsen | B15: 400000 | C15: 366993
A16: Ethan Lee | B16: 380000 | C16: 360513
A17: Lukas Schmidt | B17: 380000 | C17: 374604
A18: Alexander Müller | B18: 380000 | C18: 407089
A19: Emma Hansen | B19: 350000 | C19: 358434
A20: Olivia Jensen | B20: 350000 | C20: 381800
A21: Amelia Johnson | B21: 350000 | C21: 383744
... A34: Grand Total | B34: 12810000 | C34: 12275890

Sheet Sales Team % Target
A3: Row Labels | B3: Average of % Target Reached
A4: Alpha | B4: 1.0154602
A5: Beta | B5: 0.9555238
A6: Delta | B6: 0.94665521
A7: Epsilon | B7: 0.94503059
A8: Gamma | B8: 0.94285135
A9: Grand Total | B9: 0.96432428
